2019-10-24 14:41:42 [ERROR] Error has occurred while creating the Statement object at the ApplicationDAO because database access error has occurred or the given SQL statement has produced anything other than a single ResultSet object or such object has already been existed
by.training.certificationCenter.dao.exception.DAOException: Error has occurred while creating the Statement object at the ApplicationDAO because database access error has occurred or the given SQL statement has produced anything other than a single ResultSet object or such object has already been existed
	at by.training.certificationCenter.dao.impl.ApplicationDAO.query(ApplicationDAO.java:226) ~[classes/:?]
	at by.training.certificationCenter.service.impl.ApplicationServiceImpl.receiveAppsByUser(ApplicationServiceImpl.java:69) ~[classes/:?]
	at by.training.certificationCenter.service.impl.ApplicationServiceImplTest.testReceiveAppsByUser(ApplicationServiceImplTest.java:97) ~[test-classes/:?]
	at jdk.internal.reflect.NativeMethodAccessorImpl.invoke0(Native Method) ~[?:?]
	at jdk.internal.reflect.NativeMethodAccessorImpl.invoke(NativeMethodAccessorImpl.java:62) ~[?:?]
	at jdk.internal.reflect.DelegatingMethodAccessorImpl.invoke(DelegatingMethodAccessorImpl.java:43) ~[?:?]
	at java.lang.reflect.Method.invoke(Method.java:566) ~[?:?]
	at org.testng.internal.MethodInvocationHelper.invokeMethod(MethodInvocationHelper.java:133) ~[testng-7.0.0.jar:?]
	at org.testng.internal.TestInvoker.invokeMethod(TestInvoker.java:584) ~[testng-7.0.0.jar:?]
	at org.testng.internal.TestInvoker.invokeTestMethod(TestInvoker.java:172) ~[testng-7.0.0.jar:?]
	at org.testng.internal.MethodRunner.runInSequence(MethodRunner.java:46) ~[testng-7.0.0.jar:?]
	at org.testng.internal.TestInvoker$MethodInvocationAgent.invoke(TestInvoker.java:804) ~[testng-7.0.0.jar:?]
	at org.testng.internal.TestInvoker.invokeTestMethods(TestInvoker.java:145) ~[testng-7.0.0.jar:?]
	at org.testng.internal.TestMethodWorker.invokeTestMethods(TestMethodWorker.java:146) ~[testng-7.0.0.jar:?]
	at org.testng.internal.TestMethodWorker.run(TestMethodWorker.java:128) ~[testng-7.0.0.jar:?]
	at java.util.ArrayList.forEach(ArrayList.java:1540) [?:?]
	at org.testng.TestRunner.privateRun(TestRunner.java:770) [testng-7.0.0.jar:?]
	at org.testng.TestRunner.run(TestRunner.java:591) [testng-7.0.0.jar:?]
	at org.testng.SuiteRunner.runTest(SuiteRunner.java:402) [testng-7.0.0.jar:?]
	at org.testng.SuiteRunner.runSequentially(SuiteRunner.java:396) [testng-7.0.0.jar:?]
	at org.testng.SuiteRunner.privateRun(SuiteRunner.java:355) [testng-7.0.0.jar:?]
	at org.testng.SuiteRunner.run(SuiteRunner.java:304) [testng-7.0.0.jar:?]
	at org.testng.SuiteRunnerWorker.runSuite(SuiteRunnerWorker.java:53) [testng-7.0.0.jar:?]
	at org.testng.SuiteRunnerWorker.run(SuiteRunnerWorker.java:96) [testng-7.0.0.jar:?]
	at org.testng.TestNG.runSuitesSequentially(TestNG.java:1180) [testng-7.0.0.jar:?]
	at org.testng.TestNG.runSuitesLocally(TestNG.java:1102) [testng-7.0.0.jar:?]
	at org.testng.TestNG.runSuites(TestNG.java:1032) [testng-7.0.0.jar:?]
	at org.testng.TestNG.run(TestNG.java:1000) [testng-7.0.0.jar:?]
	at org.testng.IDEARemoteTestNG.run(IDEARemoteTestNG.java:73) [testng-plugin.jar:?]
	at org.testng.RemoteTestNGStarter.main(RemoteTestNGStarter.java:123) [testng-plugin.jar:?]
Caused by: java.sql.SQLNonTransientConnectionException: No operations allowed after connection closed.
	at com.mysql.cj.jdbc.exceptions.SQLError.createSQLException(SQLError.java:110) ~[mysql-connector-java-8.0.17.jar:8.0.17]
	at com.mysql.cj.jdbc.exceptions.SQLError.createSQLException(SQLError.java:97) ~[mysql-connector-java-8.0.17.jar:8.0.17]
	at com.mysql.cj.jdbc.exceptions.SQLError.createSQLException(SQLError.java:89) ~[mysql-connector-java-8.0.17.jar:8.0.17]
	at com.mysql.cj.jdbc.exceptions.SQLError.createSQLException(SQLError.java:63) ~[mysql-connector-java-8.0.17.jar:8.0.17]
	at com.mysql.cj.jdbc.exceptions.SQLError.createSQLException(SQLError.java:73) ~[mysql-connector-java-8.0.17.jar:8.0.17]
	at com.mysql.cj.jdbc.exceptions.SQLExceptionsMapping.translateException(SQLExceptionsMapping.java:73) ~[mysql-connector-java-8.0.17.jar:8.0.17]
	at com.mysql.cj.jdbc.ConnectionImpl.createStatement(ConnectionImpl.java:1085) ~[mysql-connector-java-8.0.17.jar:8.0.17]
	at com.mysql.cj.jdbc.ConnectionImpl.createStatement(ConnectionImpl.java:1075) ~[mysql-connector-java-8.0.17.jar:8.0.17]
	at by.training.certificationCenter.dao.impl.ApplicationDAO.query(ApplicationDAO.java:216) ~[classes/:?]
	... 29 more
Caused by: com.mysql.cj.exceptions.ConnectionIsClosedException: No operations allowed after connection closed.
	at jdk.internal.reflect.NativeConstructorAccessorImpl.newInstance0(Native Method) ~[?:?]
	at jdk.internal.reflect.NativeConstructorAccessorImpl.newInstance(NativeConstructorAccessorImpl.java:62) ~[?:?]
	at jdk.internal.reflect.DelegatingConstructorAccessorImpl.newInstance(DelegatingConstructorAccessorImpl.java:45) ~[?:?]
	at java.lang.reflect.Constructor.newInstance(Constructor.java:490) ~[?:?]
	at com.mysql.cj.exceptions.ExceptionFactory.createException(ExceptionFactory.java:61) ~[mysql-connector-java-8.0.17.jar:8.0.17]
	at com.mysql.cj.exceptions.ExceptionFactory.createException(ExceptionFactory.java:105) ~[mysql-connector-java-8.0.17.jar:8.0.17]
	at com.mysql.cj.exceptions.ExceptionFactory.createException(ExceptionFactory.java:151) ~[mysql-connector-java-8.0.17.jar:8.0.17]
	at com.mysql.cj.NativeSession.checkClosed(NativeSession.java:1209) ~[mysql-connector-java-8.0.17.jar:8.0.17]
	at com.mysql.cj.jdbc.ConnectionImpl.checkClosed(ConnectionImpl.java:567) ~[mysql-connector-java-8.0.17.jar:8.0.17]
	at com.mysql.cj.jdbc.ConnectionImpl.createStatement(ConnectionImpl.java) ~[mysql-connector-java-8.0.17.jar:8.0.17]
	at com.mysql.cj.jdbc.ConnectionImpl.createStatement(ConnectionImpl.java:1075) ~[mysql-connector-java-8.0.17.jar:8.0.17]
	at by.training.certificationCenter.dao.impl.ApplicationDAO.query(ApplicationDAO.java:216) ~[classes/:?]
	... 29 more
2019-10-24 14:50:31 [ERROR] Error has occurred while creating the Statement object at the ApplicationDAO because database access error has occurred or the given SQL statement has produced anything other than a single ResultSet object or such object has already been existed
by.training.certificationCenter.dao.exception.DAOException: Error has occurred while creating the Statement object at the ApplicationDAO because database access error has occurred or the given SQL statement has produced anything other than a single ResultSet object or such object has already been existed
	at by.training.certificationCenter.dao.impl.ApplicationDAO.query(ApplicationDAO.java:226) ~[classes/:?]
	at by.training.certificationCenter.service.impl.ApplicationServiceImpl.receiveAppsByUser(ApplicationServiceImpl.java:69) ~[classes/:?]
	at by.training.certificationCenter.service.impl.ApplicationServiceImplTest.testReceiveAppsByUser(ApplicationServiceImplTest.java:98) ~[test-classes/:?]
	at jdk.internal.reflect.NativeMethodAccessorImpl.invoke0(Native Method) ~[?:?]
	at jdk.internal.reflect.NativeMethodAccessorImpl.invoke(NativeMethodAccessorImpl.java:62) ~[?:?]
	at jdk.internal.reflect.DelegatingMethodAccessorImpl.invoke(DelegatingMethodAccessorImpl.java:43) ~[?:?]
	at java.lang.reflect.Method.invoke(Method.java:566) ~[?:?]
	at org.testng.internal.MethodInvocationHelper.invokeMethod(MethodInvocationHelper.java:133) ~[testng-7.0.0.jar:?]
	at org.testng.internal.TestInvoker.invokeMethod(TestInvoker.java:584) ~[testng-7.0.0.jar:?]
	at org.testng.internal.TestInvoker.invokeTestMethod(TestInvoker.java:172) ~[testng-7.0.0.jar:?]
	at org.testng.internal.MethodRunner.runInSequence(MethodRunner.java:46) ~[testng-7.0.0.jar:?]
	at org.testng.internal.TestInvoker$MethodInvocationAgent.invoke(TestInvoker.java:804) ~[testng-7.0.0.jar:?]
	at org.testng.internal.TestInvoker.invokeTestMethods(TestInvoker.java:145) ~[testng-7.0.0.jar:?]
	at org.testng.internal.TestMethodWorker.invokeTestMethods(TestMethodWorker.java:146) ~[testng-7.0.0.jar:?]
	at org.testng.internal.TestMethodWorker.run(TestMethodWorker.java:128) ~[testng-7.0.0.jar:?]
	at java.util.ArrayList.forEach(ArrayList.java:1540) [?:?]
	at org.testng.TestRunner.privateRun(TestRunner.java:770) [testng-7.0.0.jar:?]
	at org.testng.TestRunner.run(TestRunner.java:591) [testng-7.0.0.jar:?]
	at org.testng.SuiteRunner.runTest(SuiteRunner.java:402) [testng-7.0.0.jar:?]
	at org.testng.SuiteRunner.runSequentially(SuiteRunner.java:396) [testng-7.0.0.jar:?]
	at org.testng.SuiteRunner.privateRun(SuiteRunner.java:355) [testng-7.0.0.jar:?]
	at org.testng.SuiteRunner.run(SuiteRunner.java:304) [testng-7.0.0.jar:?]
	at org.testng.SuiteRunnerWorker.runSuite(SuiteRunnerWorker.java:53) [testng-7.0.0.jar:?]
	at org.testng.SuiteRunnerWorker.run(SuiteRunnerWorker.java:96) [testng-7.0.0.jar:?]
	at org.testng.TestNG.runSuitesSequentially(TestNG.java:1180) [testng-7.0.0.jar:?]
	at org.testng.TestNG.runSuitesLocally(TestNG.java:1102) [testng-7.0.0.jar:?]
	at org.testng.TestNG.runSuites(TestNG.java:1032) [testng-7.0.0.jar:?]
	at org.testng.TestNG.run(TestNG.java:1000) [testng-7.0.0.jar:?]
	at org.testng.IDEARemoteTestNG.run(IDEARemoteTestNG.java:73) [testng-plugin.jar:?]
	at org.testng.RemoteTestNGStarter.main(RemoteTestNGStarter.java:123) [testng-plugin.jar:?]
Caused by: java.sql.SQLNonTransientConnectionException: No operations allowed after connection closed.
	at com.mysql.cj.jdbc.exceptions.SQLError.createSQLException(SQLError.java:110) ~[mysql-connector-java-8.0.17.jar:8.0.17]
	at com.mysql.cj.jdbc.exceptions.SQLError.createSQLException(SQLError.java:97) ~[mysql-connector-java-8.0.17.jar:8.0.17]
	at com.mysql.cj.jdbc.exceptions.SQLError.createSQLException(SQLError.java:89) ~[mysql-connector-java-8.0.17.jar:8.0.17]
	at com.mysql.cj.jdbc.exceptions.SQLError.createSQLException(SQLError.java:63) ~[mysql-connector-java-8.0.17.jar:8.0.17]
	at com.mysql.cj.jdbc.exceptions.SQLError.createSQLException(SQLError.java:73) ~[mysql-connector-java-8.0.17.jar:8.0.17]
	at com.mysql.cj.jdbc.exceptions.SQLExceptionsMapping.translateException(SQLExceptionsMapping.java:73) ~[mysql-connector-java-8.0.17.jar:8.0.17]
	at com.mysql.cj.jdbc.ConnectionImpl.createStatement(ConnectionImpl.java:1085) ~[mysql-connector-java-8.0.17.jar:8.0.17]
	at com.mysql.cj.jdbc.ConnectionImpl.createStatement(ConnectionImpl.java:1075) ~[mysql-connector-java-8.0.17.jar:8.0.17]
	at by.training.certificationCenter.dao.impl.ApplicationDAO.query(ApplicationDAO.java:216) ~[classes/:?]
	... 29 more
Caused by: com.mysql.cj.exceptions.ConnectionIsClosedException: No operations allowed after connection closed.
	at jdk.internal.reflect.NativeConstructorAccessorImpl.newInstance0(Native Method) ~[?:?]
	at jdk.internal.reflect.NativeConstructorAccessorImpl.newInstance(NativeConstructorAccessorImpl.java:62) ~[?:?]
	at jdk.internal.reflect.DelegatingConstructorAccessorImpl.newInstance(DelegatingConstructorAccessorImpl.java:45) ~[?:?]
	at java.lang.reflect.Constructor.newInstance(Constructor.java:490) ~[?:?]
	at com.mysql.cj.exceptions.ExceptionFactory.createException(ExceptionFactory.java:61) ~[mysql-connector-java-8.0.17.jar:8.0.17]
	at com.mysql.cj.exceptions.ExceptionFactory.createException(ExceptionFactory.java:105) ~[mysql-connector-java-8.0.17.jar:8.0.17]
	at com.mysql.cj.exceptions.ExceptionFactory.createException(ExceptionFactory.java:151) ~[mysql-connector-java-8.0.17.jar:8.0.17]
	at com.mysql.cj.NativeSession.checkClosed(NativeSession.java:1209) ~[mysql-connector-java-8.0.17.jar:8.0.17]
	at com.mysql.cj.jdbc.ConnectionImpl.checkClosed(ConnectionImpl.java:567) ~[mysql-connector-java-8.0.17.jar:8.0.17]
	at com.mysql.cj.jdbc.ConnectionImpl.createStatement(ConnectionImpl.java) ~[mysql-connector-java-8.0.17.jar:8.0.17]
	at com.mysql.cj.jdbc.ConnectionImpl.createStatement(ConnectionImpl.java:1075) ~[mysql-connector-java-8.0.17.jar:8.0.17]
	at by.training.certificationCenter.dao.impl.ApplicationDAO.query(ApplicationDAO.java:216) ~[classes/:?]
	... 29 more
2019-10-24 14:52:51 [ERROR] Error has occurred while creating the Statement object at the ApplicationDAO because database access error has occurred or the given SQL statement has produced anything other than a single ResultSet object or such object has already been existed
by.training.certificationCenter.dao.exception.DAOException: Error has occurred while creating the Statement object at the ApplicationDAO because database access error has occurred or the given SQL statement has produced anything other than a single ResultSet object or such object has already been existed
	at by.training.certificationCenter.dao.impl.ApplicationDAO.query(ApplicationDAO.java:226) ~[classes/:?]
	at by.training.certificationCenter.service.impl.ApplicationServiceImpl.receiveAppsByUser(ApplicationServiceImpl.java:69) ~[classes/:?]
	at by.training.certificationCenter.service.impl.ApplicationServiceImplTest.testReceiveAppsByUser(ApplicationServiceImplTest.java:98) ~[test-classes/:?]
	at jdk.internal.reflect.NativeMethodAccessorImpl.invoke0(Native Method) ~[?:?]
	at jdk.internal.reflect.NativeMethodAccessorImpl.invoke(NativeMethodAccessorImpl.java:62) ~[?:?]
	at jdk.internal.reflect.DelegatingMethodAccessorImpl.invoke(DelegatingMethodAccessorImpl.java:43) ~[?:?]
	at java.lang.reflect.Method.invoke(Method.java:566) ~[?:?]
	at org.testng.internal.MethodInvocationHelper.invokeMethod(MethodInvocationHelper.java:133) ~[testng-7.0.0.jar:?]
	at org.testng.internal.TestInvoker.invokeMethod(TestInvoker.java:584) ~[testng-7.0.0.jar:?]
	at org.testng.internal.TestInvoker.invokeTestMethod(TestInvoker.java:172) ~[testng-7.0.0.jar:?]
	at org.testng.internal.MethodRunner.runInSequence(MethodRunner.java:46) ~[testng-7.0.0.jar:?]
	at org.testng.internal.TestInvoker$MethodInvocationAgent.invoke(TestInvoker.java:804) ~[testng-7.0.0.jar:?]
	at org.testng.internal.TestInvoker.invokeTestMethods(TestInvoker.java:145) ~[testng-7.0.0.jar:?]
	at org.testng.internal.TestMethodWorker.invokeTestMethods(TestMethodWorker.java:146) ~[testng-7.0.0.jar:?]
	at org.testng.internal.TestMethodWorker.run(TestMethodWorker.java:128) ~[testng-7.0.0.jar:?]
	at java.util.ArrayList.forEach(ArrayList.java:1540) [?:?]
	at org.testng.TestRunner.privateRun(TestRunner.java:770) [testng-7.0.0.jar:?]
	at org.testng.TestRunner.run(TestRunner.java:591) [testng-7.0.0.jar:?]
	at org.testng.SuiteRunner.runTest(SuiteRunner.java:402) [testng-7.0.0.jar:?]
	at org.testng.SuiteRunner.runSequentially(SuiteRunner.java:396) [testng-7.0.0.jar:?]
	at org.testng.SuiteRunner.privateRun(SuiteRunner.java:355) [testng-7.0.0.jar:?]
	at org.testng.SuiteRunner.run(SuiteRunner.java:304) [testng-7.0.0.jar:?]
	at org.testng.SuiteRunnerWorker.runSuite(SuiteRunnerWorker.java:53) [testng-7.0.0.jar:?]
	at org.testng.SuiteRunnerWorker.run(SuiteRunnerWorker.java:96) [testng-7.0.0.jar:?]
	at org.testng.TestNG.runSuitesSequentially(TestNG.java:1180) [testng-7.0.0.jar:?]
	at org.testng.TestNG.runSuitesLocally(TestNG.java:1102) [testng-7.0.0.jar:?]
	at org.testng.TestNG.runSuites(TestNG.java:1032) [testng-7.0.0.jar:?]
	at org.testng.TestNG.run(TestNG.java:1000) [testng-7.0.0.jar:?]
	at org.testng.IDEARemoteTestNG.run(IDEARemoteTestNG.java:73) [testng-plugin.jar:?]
	at org.testng.RemoteTestNGStarter.main(RemoteTestNGStarter.java:123) [testng-plugin.jar:?]
Caused by: java.sql.SQLNonTransientConnectionException: No operations allowed after connection closed.
	at com.mysql.cj.jdbc.exceptions.SQLError.createSQLException(SQLError.java:110) ~[mysql-connector-java-8.0.17.jar:8.0.17]
	at com.mysql.cj.jdbc.exceptions.SQLError.createSQLException(SQLError.java:97) ~[mysql-connector-java-8.0.17.jar:8.0.17]
	at com.mysql.cj.jdbc.exceptions.SQLError.createSQLException(SQLError.java:89) ~[mysql-connector-java-8.0.17.jar:8.0.17]
	at com.mysql.cj.jdbc.exceptions.SQLError.createSQLException(SQLError.java:63) ~[mysql-connector-java-8.0.17.jar:8.0.17]
	at com.mysql.cj.jdbc.exceptions.SQLError.createSQLException(SQLError.java:73) ~[mysql-connector-java-8.0.17.jar:8.0.17]
	at com.mysql.cj.jdbc.exceptions.SQLExceptionsMapping.translateException(SQLExceptionsMapping.java:73) ~[mysql-connector-java-8.0.17.jar:8.0.17]
	at com.mysql.cj.jdbc.ConnectionImpl.createStatement(ConnectionImpl.java:1085) ~[mysql-connector-java-8.0.17.jar:8.0.17]
	at com.mysql.cj.jdbc.ConnectionImpl.createStatement(ConnectionImpl.java:1075) ~[mysql-connector-java-8.0.17.jar:8.0.17]
	at by.training.certificationCenter.dao.impl.ApplicationDAO.query(ApplicationDAO.java:216) ~[classes/:?]
	... 29 more
Caused by: com.mysql.cj.exceptions.ConnectionIsClosedException: No operations allowed after connection closed.
	at jdk.internal.reflect.NativeConstructorAccessorImpl.newInstance0(Native Method) ~[?:?]
	at jdk.internal.reflect.NativeConstructorAccessorImpl.newInstance(NativeConstructorAccessorImpl.java:62) ~[?:?]
	at jdk.internal.reflect.DelegatingConstructorAccessorImpl.newInstance(DelegatingConstructorAccessorImpl.java:45) ~[?:?]
	at java.lang.reflect.Constructor.newInstance(Constructor.java:490) ~[?:?]
	at com.mysql.cj.exceptions.ExceptionFactory.createException(ExceptionFactory.java:61) ~[mysql-connector-java-8.0.17.jar:8.0.17]
	at com.mysql.cj.exceptions.ExceptionFactory.createException(ExceptionFactory.java:105) ~[mysql-connector-java-8.0.17.jar:8.0.17]
	at com.mysql.cj.exceptions.ExceptionFactory.createException(ExceptionFactory.java:151) ~[mysql-connector-java-8.0.17.jar:8.0.17]
	at com.mysql.cj.NativeSession.checkClosed(NativeSession.java:1209) ~[mysql-connector-java-8.0.17.jar:8.0.17]
	at com.mysql.cj.jdbc.ConnectionImpl.checkClosed(ConnectionImpl.java:567) ~[mysql-connector-java-8.0.17.jar:8.0.17]
	at com.mysql.cj.jdbc.ConnectionImpl.createStatement(ConnectionImpl.java) ~[mysql-connector-java-8.0.17.jar:8.0.17]
	at com.mysql.cj.jdbc.ConnectionImpl.createStatement(ConnectionImpl.java:1075) ~[mysql-connector-java-8.0.17.jar:8.0.17]
	at by.training.certificationCenter.dao.impl.ApplicationDAO.query(ApplicationDAO.java:216) ~[classes/:?]
	... 29 more
